<mujoco model="skid_steer_rover">
    <default>
        <joint type="hinge" axis="0 1 0" damping="5.0"/>
        <geom friction="1 0.005 0.0001"/>
    </default>
    <asset>
        
    </asset>

    <worldbody>

        <body name="player_rover" pos="0 0 0.5">
            <joint type="free" name="rover_root"/>
            
            <camera name="chase_cam" mode="fixed" pos="-3 0 1.5" xyaxes="0 -1 0 0.3 0 1"/>

            <geom name="chassis" type="box" size="0.5 0.25 0.1" material="obsidian" mass="10"/>

            <body name="rover_gun_base" pos="-0.18 0 0.17">
                <geom type="capsule" size="0.15 0.07" material="obsidian" mass="5"/>
                
                <body name="rover_barrel" pos="0 0 0.07">
                    <joint name="gun_tilt" type="hinge" axis="0 1 0" limited="true" range="-45 45"/>
                    
                    <geom type="cylinder" size="0.03 0.4" pos="0.4 0 0" euler="0 90 0" material="gold" mass="1"/>
                    <site name="muzzle" pos="0.85 0 0" size="0.01" rgba="1 0 0 0"/>
                </body>
            </body>

            <body name="wheel_fl" pos="0.4 0.35 0">
                <joint name="joint_fl"/>
                <geom type="cylinder" size="0.15 0.05" rgba="0.1 0.1 0.1 1" euler="90 0 0"/>
            </body>

            <body name="wheel_fr" pos="0.4 -0.35 0">
                <joint name="joint_fr"/>
                <geom type="cylinder" size="0.15 0.05" material="rover_tires" euler="90 0 0"/>
            </body>

            <body name="wheel_ml" pos="0 0.35 0">
                <joint name="joint_ml"/>
                <geom type="cylinder" size="0.15 0.05" material="rover_tires" euler="90 0 0"/>
            </body>

            <body name="wheel_mr" pos="0 -0.35 0">
                <joint name="joint_mr"/>
                <geom type="cylinder" size="0.15 0.05" material="rover_tires" euler="90 0 0"/>
            </body>

            <body name="wheel_bl" pos="-0.4 0.35 0">
                <joint name="joint_bl"/>
                <geom type="cylinder" size="0.15 0.05" material="rover_tires" euler="90 0 0"/>
            </body>

            <body name="wheel_br" pos="-0.4 -0.35 0">
                <joint name="joint_br"/>
                <geom type="cylinder" size="0.15 0.05" material="rover_tires" euler="90 0 0"/>
            </body>
        </body>
    </worldbody>

    <actuator>
        <motor name="motor_fl" joint="joint_fl" gear="1" ctrllimited="true" ctrlrange="-50 50"/>
        <motor name="motor_fr" joint="joint_fr" gear="1" ctrllimited="true" ctrlrange="-50 50"/>
        <motor name="motor_ml" joint="joint_ml" gear="1" ctrllimited="true" ctrlrange="-50 50"/>
        <motor name="motor_mr" joint="joint_mr" gear="1" ctrllimited="true" ctrlrange="-50 50"/>
        <motor name="motor_bl" joint="joint_bl" gear="1" ctrllimited="true" ctrlrange="-50 50"/>
        <motor name="motor_br" joint="joint_br" gear="1" ctrllimited="true" ctrlrange="-50 50"/>
        <position name="act_gun_tilt" joint="gun_tilt" kp="50" ctrllimited="true" ctrlrange="-0.1 0.1"/>
    </actuator>

</mujoco>